Workbook

Sheet Sprints
A1: SentinelAI · Plan de sprints (18 semanas)
A2: Proyecto de Título · Capstone · Duoc UC · Grupo 3
A4: Fecha de inicio (lunes de la semana 1): | D4: 46272 | E4: ← editable. Todas las fechas de abajo se recalculan a partir de esta celda.
A6: Sprint | B6: Semanas | C6: Bloque | D6: Inicio | E6: Fin | F6: Objetivo del sprint | G6: Hito verificable | H6: Tareas | I6: Días est. | J6: Cerradas | K6: % Avance
A7: S1 | B7: 1-2 | C7: Laboratorio e ingesta | D7: =$D$4 -> 46272 | E7: =D7+13 -> 46285 | F7: Dejar el laboratorio en pie y despejar el riesgo del LLM antes de comprometerse con la arquitectura. | G7: docker compose up levanta el laboratorio aislado y existe un JSON de ZAP guardado más una medición real de latencia de Ollama. | H7: =COUNTIFS(Backlog!$B$2:$B$72,$A7) -> 10 | I7: =SUMIFS(Backlog!$I$2:$I$72,Backlog!$B$2:$B$72,$A7) -> 14 | J7: =COUNTIFS(Backlog!$B$2:$B$72,$A7,Backlog!$L$2:$L$72,"Hecho") -> 0 | K7: =IFERROR(J7/H7,0) -> 0
A8: S2 | B8: 3-4 | C8: Laboratorio e ingesta | D8: =D7+14 -> 46286 | E8: =D8+13 -> 46299 | F8: Construir el modelo de datos que sostiene todo lo demás. | G8: alembic upgrade head crea el esquema completo sobre una base vacía y el DER está documentado. | H8: =COUNTIFS(Backlog!$B$2:$B$72,$A8) -> 8 | I8: =SUMIFS(Backlog!$I$2:$I$72,Backlog!$B$2:$B$72,$A8) -> 14 | J8: =COUNTIFS(Backlog!$B$2:$B$72,$A8,Backlog!$L$2:$L$72,"Hecho") -> 0 | K8: =IFERROR(J8/H8,0) -> 0
A9: S3 | B9: 5-6 | C9: Laboratorio e ingesta | D9: =D8+14 -> 46300 | E9: =D9+13 -> 46313 | F9: Cerrar el camino de escaneo a consulta con hallazgos normalizados y sin duplicados. | G9: HITO 1: se importa un escaneo real de ZAP y se consulta por API con severidad unificada y sin duplicados. | H9: =COUNTIFS(Backlog!$B$2:$B$72,$A9) -> 9 | I9: =SUMIFS(Backlog!$I$2:$I$72,Backlog!$B$2:$B$72,$A9) -> 15 | J9: =COUNTIFS(Backlog!$B$2:$B$72,$A9,Backlog!$L$2:$L$72,"Hecho") -> 0 | K9: =IFERROR(J9/H9,0) -> 0
A10: S4 | B10: 7-8 | C10: IA local | D10: =D9+14 -> 46314 | E10: =D10+13 -> 46327 | F10: Lograr que el modelo devuelva estructura confiable, no texto libre. | G10: Un hallazgo entra y sale con explicación, categoría OWASP, prioridad, confianza y remediación, validado por esquema. | H10: =COUNTIFS(Backlog!$B$2:$B$72,$A10) -> 7 | I10: =SUMIFS(Backlog!$I$2:$I$72,Backlog!$B$2:$B$72,$A10) -> 14 | J10: =COUNTIFS(Backlog!$B$2:$B$72,$A10,Backlog!$L$2:$L$72,"Hecho") -> 0 | K10: =IFERROR(J10/H10,0) -> 0
A11: S5 | B11: 9-10 | C11: IA local | D11: =D10+14 -> 46328 | E11: =D11+13 -> 46341 | F11: Enriquecer escaneos completos sin bloquear la aplicación y dejando rastro auditable. | G11: Un escaneo completo se enriquece en segundo plano y cada salida guarda su prompt y versión de modelo. | H11: =COUNTIFS(Backlog!$B$2:$B$72,$A11) -> 6 | I11: =SUMIFS(Backlog!$I$2:$I$72,Backlog!$B$2:$B$72,$A11) -> 12 | J11: =COUNTIFS(Backlog!$B$2:$B$72,$A11,Backlog!$L$2:$L$72,"Hecho") -> 0 | K11: =IFERROR(J11/H11,0) -> 0
A12: S6 | B12: 11-12 | C12: IA local | D12: =D11+14 -> 46342 | E12: =D12+13 -> 46355 | F12: Medir la calidad de la IA contra anotación humana. Es lo que convierte la demo en resultado defendible. | G12: HITO 2: métricas de acierto OWASP, acierto de prioridad y tasa de alucinación, calculadas de forma reproducible. | H12: =COUNTIFS(Backlog!$B$2:$B$72,$A12) -> 8 | I12: =SUMIFS(Backlog!$I$2:$I$72,Backlog!$B$2:$B$72,$A12) -> 15 | J12: =COUNTIFS(Backlog!$B$2:$B$72,$A12,Backlog!$L$2:$L$72,"Hecho") -> 0 | K12: =IFERROR(J12/H12,0) -> 0
A13: S7 | B13: 13-14 | C13: Dashboard y cierre | D13: =D12+14 -> 46356 | E13: =D13+13 -> 46369 | F13: Hacer visible y filtrable lo que ya funciona por debajo. | G13: El dashboard muestra el resumen, filtra hallazgos y presenta evidencia original junto a la salida de la IA. | H13: =COUNTIFS(Backlog!$B$2:$B$72,$A13) -> 7 | I13: =SUMIFS(Backlog!$I$2:$I$72,Backlog!$B$2:$B$72,$A13) -> 17 | J13: =COUNTIFS(Backlog!$B$2:$B$72,$A13,Backlog!$L$2:$L$72,"Hecho") -> 0 | K13: =IFERROR(J13/H13,0) -> 0
A14: S8 | B14: 15-16 | C14: Dashboard y cierre | D14: =D13+14 -> 46370 | E14: =D14+13 -> 46383 | F14: Cerrar validación humana e informe, y congelar el código. | G14: Flujo completo de escaneo a informe exportable con validación registrada. Congelamiento al cierre de la semana 16. | H14: =COUNTIFS(Backlog!$B$2:$B$72,$A14) -> 8 | I14: =SUMIFS(Backlog!$I$2:$I$72,Backlog!$B$2:$B$72,$A14) -> 17 | J14: =COUNTIFS(Backlog!$B$2:$B$72,$A14,Backlog!$L$2:$L$72,"Hecho") -> 0 | K14: =IFERROR(J14/H14,0) -> 0
A15: S9 | B15: 17-18 | C15: Dashboard y cierre | D15: =D14+14 -> 46384 | E15: =D15+13 -> 46397 | F15: Documentar, reunir evidencias y ensayar la defensa. | G15: Carpeta de evidencias completa, README reproducible, video de respaldo grabado y presentación ensayada. | H15: =COUNTIFS(Backlog!$B$2:$B$72,$A15) -> 8 | I15: =SUMIFS(Backlog!$I$2:$I$72,Backlog!$B$2:$B$72,$A15) -> 15 | J15: =COUNTIFS(Backlog!$B$2:$B$72,$A15,Backlog!$L$2:$L$72,"Hecho") -> 0 | K15: =IFERROR(J15/H15,0) -> 0
A16: TOTAL | D16: =D7 -> 46272 | E16: =E15 -> 46397 | H16: =SUM(H7:H15) -> 71 | I16: =SUM(I7:I15) -> 133 | J16: =SUM(J7:J15) -> 0 | K16: =IFERROR(J16/H16,0) -> 0
A18: Supuesto: la fecha de inicio (07-09-2026) la fijamos nosotros. 18 semanas corridas desde ahí terminan el 10-01-2027, así que ajústenla o descuenten el receso de fin de año según el calendario académico de Duoc.
A19: Días est. es esfuerzo en días-persona, no días de calendario. Con 3 integrantes, un sprint de 2 semanas admite del orden de 18 a 20 días-persona si el proyecto convive con otros ramos.

Sheet Backlog
A1: ID | B1: Sprint | C1: Semanas | D1: Área | E1: Tarea | F1: Criterio de aceptación | G1: Rol responsable | H1: Responsable | I1: Días est. | J1: Depende de | K1: Prioridad | L1: Estado
A2: T-001 | B2: S1 | C2: 1-2 | D2: Preparación | E2: Definir el esquema JSON normalizado del hallazgo | F2: Documento en /docs con cada campo, tipo, obligatoriedad y ejemplo. Revisado y aprobado por los 3 integrantes. | G2: Arquitectura e IA | I2: 2 | K2: Alta | L2: Pendiente
A3: T-002 | B3: S1 | C3: 1-2 | D3: Preparación | E3: Definir la máquina de estados del hallazgo | F3: Diagrama con estados (nuevo, en triage, confirmado, falso positivo, remediado) y quién ejecuta cada transición. | G3: Arquitectura e IA | I3: 1 | J3: T-001 | K3: Alta | L3: Pendiente
A4: T-003 | B4: S1 | C4: 1-2 | D4: Preparación | E4: Crear repositorio monorepo con estructura base | F4: Repo con /backend /frontend /lab /docs, README inicial y .gitignore. Acceso para los 3 integrantes. | G4: Backend, Datos y Dashboard | H4: Luciano Zambrano | I4: 1 | K4: Alta | L4: Pendiente
A5: T-004 | B5: S1 | C5: 1-2 | D5: Preparación | E5: Definir convenciones de commits, ramas y política de PR | F5: CONTRIBUTING.md con formato de commit, naming de ramas y regla de al menos 1 revisor por PR. | G5: Backend, Datos y Dashboard | H5: Luciano Zambrano | I5: 1 | J5: T-003 | K5: Media | L5: Pendiente
A6: T-005 | B6: S1 | C6: 1-2 | D6: Laboratorio | E6: Docker Compose con Juice Shop y PostgreSQL en red interna | F6: docker compose up levanta ambos servicios en una red bridge dedicada, sin puertos publicados hacia afuera. | G6: Laboratorio y Validación | I6: 2 | K6: Alta | L6: Pendiente
A7: T-006 | B7: S1 | C7: 1-2 | D7: Laboratorio | E7: Verificar el aislamiento de red del laboratorio | F7: Evidencia (captura o log) de que el contenedor objetivo no alcanza internet ni la LAN del host. | G7: Laboratorio y Validación | I7: 1 | J7: T-005 | K7: Alta | L7: Pendiente
A8: T-007 | B8: S1 | C8: 1-2 | D8: Laboratorio | E8: Ejecutar primer escaneo ZAP baseline y guardar el JSON crudo | F8: Archivo JSON versionado en /lab/fixtures que sirve de insumo fijo para desarrollar sin re-escanear. | G8: Laboratorio y Validación | I8: 1 | J8: T-005 | K8: Alta | L8: Pendiente
A9: T-008 | B9: S1 | C9: 1-2 | D9: IA | E9: Prueba de humo de Ollama con modelo cuantizado | F9: Un hallazgo real procesado localmente. Registrar latencia por hallazgo, RAM y VRAM usadas en el equipo más débil del equipo. | G9: Arquitectura e IA | I9: 2 | K9: Alta | L9: Pendiente
A10: T-009 | B10: S1 | C10: 1-2 | D10: IA | E10: Decidir el modelo LLM definitivo según la prueba de humo | F10: Decisión escrita en /docs con el modelo elegido, su tamaño y la latencia medida. Si no cumple, plan B documentado. | G10: Arquitectura e IA | I10: 1 | J10: T-008 | K10: Alta | L10: Pendiente
A11: T-010 | B11: S1 | C11: 1-2 | D11: Backend | E11: Esqueleto FastAPI con healthcheck dentro del compose | F11: GET /health responde 200 desde el contenedor y el servicio arranca junto al resto del laboratorio. | G11: Backend, Datos y Dashboard | H11: Luciano Zambrano | I11: 2 | J11: T-003 | K11: Alta | L11: Pendiente
A12: T-011 | B12: S2 | C12: 3-4 | D12: Backend | E12: Diagrama entidad-relación del modelo de datos | F12: DER con target, scan, tool, finding, finding_ai y validation, con cardinalidades y claves. | G12: Backend, Datos y Dashboard | H12: Luciano Zambrano | I12: 2 | J12: T-001 | K12: Alta | L12: Pendiente
A13: T-012 | B13: S2 | C13: 3-4 | D13: Backend | E13: Implementar los modelos SQLAlchemy | F13: Modelos que reflejan el DER, con tipos correctos y relaciones navegables desde el ORM. | G13: Backend, Datos y Dashboard | H13: Luciano Zambrano | I13: 3 | J13: T-011 | K13: Alta | L13: Pendiente
A14: T-013 | B14: S2 | C14: 3-4 | D14: Backend | E14: Configurar Alembic y generar la migración inicial | F14: alembic upgrade head crea el esquema completo sobre una base vacía, sin intervención manual. | G14: Backend, Datos y Dashboard | H14: Luciano Zambrano | I14: 2 | J14: T-012 | K14: Alta | L14: Pendiente
A15: T-014 | B15: S2 | C15: 3-4 | D15: Arquitectura | E15: Definir e implementar la regla de deduplicación (dedupe_key) | F15: Regla documentada (qué campos la componen y por qué) más función que la calcula, con tests. | G15: Arquitectura e IA | I15: 2 | J15: T-001 | K15: Alta | L15: Pendiente
A16: T-015 | B16: S2 | C16: 3-4 | D16: Backend | E16: Crear índices sobre scan_id, severidad y dedupe_key | F16: Índices en la migración. Consulta de listado sobre datos de prueba responde por debajo de 500 ms. | G16: Backend, Datos y Dashboard | H16: Luciano Zambrano | I16: 1 | J16: T-013 | K16: Media | L16: Pendiente
A17: T-016 | B17: S2 | C17: 3-4 | D17: Backend | E17: Script de carga de datos de prueba desde el fixture ZAP | F17: Comando único que puebla la base con datos realistas para desarrollar el frontend más adelante. | G17: Backend, Datos y Dashboard | H17: Luciano Zambrano | I17: 1 | J17: T-013 | K17: Media | L17: Pendiente
A18: T-017 | B18: S2 | C18: 3-4 | D18: Backend | E18: Documentar el modelo de datos en /docs | F18: Documento con el DER, el diccionario de datos y las decisiones de diseño. Entra en la carpeta de evidencias. | G18: Backend, Datos y Dashboard | H18: Luciano Zambrano | I18: 1 | J18: T-011 | K18: Media | L18: Pendiente
A19: T-018 | B19: S2 | C19: 3-4 | D19: Laboratorio | E19: Automatizar la ejecución del escaneo ZAP por script | F19: Un comando lanza el escaneo contra Juice Shop y deja el JSON en una ruta conocida, sin pasos manuales. | G19: Laboratorio y Validación | I19: 2 | J19: T-007 | K19: Media | L19: Pendiente
A20: T-019 | B20: S3 | C20: 5-6 | D20: Backend | E20: Parser de ZAP JSON al esquema normalizado | F20: El parser convierte el fixture completo sin perder hallazgos y sin campos obligatorios vacíos. | G20: Backend, Datos y Dashboard | H20: Luciano Zambrano | I20: 3 | J20: T-001 | K20: Alta | L20: Pendiente
A21: T-020 | B21: S3 | C21: 5-6 | D21: Arquitectura | E21: Mapeo de severidad de la herramienta a la escala común | F21: Tabla de equivalencias documentada y justificada. Se aplica en la ingesta, no en la vista. | G21: Arquitectura e IA | I21: 1 | J21: T-019 | K21: Alta | L21: Pendiente
A22: T-021 | B22: S3 | C22: 5-6 | D22: Backend | E22: Conservar la evidencia original íntegra junto al hallazgo | F22: El registro guarda el bloque crudo de la herramienta sin modificar, recuperable desde la API. | G22: Backend, Datos y Dashboard | H22: Luciano Zambrano | I22: 1 | J22: T-019 | K22: Alta | L22: Pendiente
A23: T-022 | B23: S3 | C23: 5-6 | D23: Backend | E23: Endpoint POST /scans/import | F23: Recibe un JSON de ZAP, persiste escaneo y hallazgos normalizados, y devuelve el resumen de la importación. | G23: Backend, Datos y Dashboard | H23: Luciano Zambrano | I23: 2 | J23: T-019 | K23: Alta | L23: Pendiente
A24: T-023 | B24: S3 | C24: 5-6 | D24: Backend | E24: Endpoint GET /findings con filtros y paginación | F24: Filtra por severidad, estado, categoría y escaneo. Respuesta paginada y con total de coincidencias. | G24: Backend, Datos y Dashboard | H24: Luciano Zambrano | I24: 2 | J24: T-022 | K24: Alta | L24: Pendiente
A25: T-024 | B25: S3 | C25: 5-6 | D25: Backend | E25: Aplicar deduplicación en la ingesta agrupando ocurrencias | F25: Reimportar el mismo escaneo no duplica registros. Cada hallazgo agrupado indica cuántas veces se reportó. | G25: Backend, Datos y Dashboard | H25: Luciano Zambrano | I25: 2 | J25: T-014 | K25: Alta | L25: Pendiente
A26: T-025 | B26: S3 | C26: 5-6 | D26: Backend | E26: Tests unitarios del parser con fixtures reales | F26: Cobertura de los casos límite: campos ausentes, evidencia vacía, severidad desconocida y hallazgo repetido. | G26: Backend, Datos y Dashboard | H26: Luciano Zambrano | I26: 2 | J26: T-019 | K26: Media | L26: Pendiente
A27: T-026 | B27: S3 | C27: 5-6 | D27: Backend | E27: Colección de pruebas de la API versionada en el repo | F27: Colección Postman o Bruno que recorre importar, listar y filtrar. Es evidencia entregable del proyecto. | G27: Backend, Datos y Dashboard | H27: Luciano Zambrano | I27: 1 | J27: T-023 | K27: Alta | L27: Pendiente
A28: T-027 | B28: S3 | C28: 5-6 | D28: Validación | E28: HITO 1: importar un escaneo real y consultarlo sin duplicados | F28: Demo de extremo a extremo con datos reales, sin pasos manuales entre el escaneo y la consulta por API. | G28: Laboratorio y Validación | I28: 1 | J28: T-024 | K28: Alta | L28: Pendiente
A29: T-028 | B29: S4 | C29: 7-8 | D29: IA | E29: Cliente de Ollama con timeout y reintentos | F29: Módulo aislado, configurable por variables de entorno, que no cuelga la aplicación si el modelo no responde. | G29: Arquitectura e IA | I29: 2 | J29: T-009 | K29: Alta | L29: Pendiente
A30: T-029 | B30: S4 | C30: 7-8 | D30: IA | E30: Diseñar el prompt con salida JSON estricta | F30: El prompt pide explicación, categoría OWASP Top 10, prioridad sugerida, confianza y remediación concreta. | G30: Arquitectura e IA | I30: 3 | J30: T-028 | K30: Alta | L30: Pendiente
A31: T-030 | B31: S4 | C31: 7-8 | D31: IA | E31: Esquema Pydantic que valida la salida del modelo | F31: Toda respuesta pasa por validación. Categoría fuera del OWASP Top 10 o confianza fuera de rango se rechaza. | G31: Arquitectura e IA | I31: 2 | J31: T-029 | K31: Alta | L31: Pendiente
A32: T-031 | B32: S4 | C32: 7-8 | D32: IA | E32: Reintento con reparación y marca de 'sin enriquecer' | F32: Tras 3 intentos fallidos el hallazgo queda marcado y visible como no enriquecido. Nunca se inventa el campo. | G32: Arquitectura e IA | I32: 2 | J32: T-030 | K32: Alta | L32: Pendiente
A33: T-032 | B33: S4 | C33: 7-8 | D33: Backend | E33: Endpoint POST /findings/{id}/enrich | F33: Dispara el enriquecimiento de un hallazgo y devuelve la salida validada o el motivo del fallo. | G33: Backend, Datos y Dashboard | H33: Luciano Zambrano | I33: 2 | J33: T-030 | K33: Alta | L33: Pendiente
A34: T-033 | B34: S4 | C34: 7-8 | D34: IA | E34: Iterar el prompt sobre 10 hallazgos representativos | F34: Registro de las versiones del prompt probadas y qué mejoró cada una. Insumo directo del golden set. | G34: Arquitectura e IA | I34: 2 | J34: T-029 | K34: Media | L34: Pendiente
A35: T-034 | B35: S4 | C35: 7-8 | D35: IA | E35: Documentar prompt, versión del modelo y parámetros | F35: Documento con el prompt final, temperatura, contexto y versión exacta del modelo, para poder reproducir resultados. | G35: Arquitectura e IA | I35: 1 | J35: T-033 | K35: Alta | L35: Pendiente
A36: T-035 | B36: S5 | C36: 9-10 | D36: Backend | E36: Persistir la salida IA con prompt, modelo y timestamp | F36: La tabla finding_ai guarda qué prompt y qué versión del modelo generaron cada salida. Auditable meses después. | G36: Backend, Datos y Dashboard | H36: Luciano Zambrano | I36: 2 | J36: T-032 | K36: Alta | L36: Pendiente
A37: T-036 | B37: S5 | C37: 9-10 | D37: Backend | E37: Cola de trabajos para enriquecer un escaneo completo | F37: El enriquecimiento por lote corre en segundo plano. La API sigue respondiendo mientras el modelo trabaja. | G37: Backend, Datos y Dashboard | H37: Luciano Zambrano | I37: 3 | J37: T-032 | K37: Alta | L37: Pendiente
A38: T-037 | B38: S5 | C38: 9-10 | D38: Backend | E38: Endpoint de estado del trabajo de enriquecimiento | F38: Devuelve progreso, procesados, fallidos y tiempo transcurrido. El dashboard lo usará para mostrar avance. | G38: Backend, Datos y Dashboard | H38: Luciano Zambrano | I38: 2 | J38: T-036 | K38: Alta | L38: Pendiente
A39: T-038 | B39: S5 | C39: 9-10 | D39: Backend | E39: Reprocesar hallazgos fallidos de forma idempotente | F39: Relanzar el trabajo solo procesa lo pendiente y no duplica registros de enriquecimiento. | G39: Backend, Datos y Dashboard | H39: Luciano Zambrano | I39: 2 | J39: T-036 | K39: Media | L39: Pendiente
A40: T-039 | B40: S5 | C40: 9-10 | D40: IA | E40: Medir el tiempo total de enriquecimiento de un escaneo completo | F40: Número documentado (hallazgos por minuto). Si el escaneo completo tarda demasiado, decidir mitigación aquí y no en la semana 17. | G40: Arquitectura e IA | I40: 1 | J40: T-036 | K40: Alta | L40: Pendiente
...

Sheet Riesgos
A1: Registro de riesgos
A3: ID | B3: Riesgo | C3: Prob. (1-5) | D3: Impacto (1-5) | E3: Exposición | F3: Mitigación | G3: Señal de alerta temprana | H3: Sprint en que se despeja
A4: R-01 | B4: Hardware insuficiente para correr el LLM local | C4: 4 | D4: 5 | E4: =C4*D4 -> 20 | F4: Prueba de humo en la semana 1 con modelo cuantizado de 7-8B. Si no rinde, bajar de tamaño o enriquecer solo los hallazgos de severidad alta. | G4: Latencia por hallazgo sobre 30 segundos o swap del sistema durante la prueba. | H4: S1
A5: R-02 | B5: El modelo devuelve JSON inválido o inventa categorías | C5: 4 | D5: 3 | E5: =C5*D5 -> 12 | F5: Modo JSON de Ollama más validación con Pydantic, reintento con reparación y marca de 'sin enriquecer' tras 3 fallos. | G5: Más de un 10% de salidas rechazadas por el validador en las pruebas del S4. | H5: S4
A6: R-03 | B6: El esquema normalizado cambia después de construir el backend | C6: 3 | D6: 5 | E6: =C6*D6 -> 15 | F6: Congelar el esquema en la semana 1 y revisarlo entre los 3. Cualquier cambio posterior pasa por migración Alembic. | G6: Aparece un campo necesario que no estaba previsto durante el S3. | H6: S1
A7: R-04 | B7: Expansión del alcance hacia Nikto, OpenVAS, DVWA o WebGoat | C7: 4 | D7: 4 | E7: =C7*D7 -> 16 | F7: Están marcados como opcionales en la propuesta. No se tocan hasta que el flujo ZAP a Juice Shop esté cerrado y medido. | G7: Se abre una tarea de herramienta opcional antes de cerrar el HITO 2. | H7: S7
A8: R-05 | B8: Carga desbalanceada sobre backend, datos y dashboard | C8: 4 | D8: 3 | E8: =C8*D8 -> 12 | F8: Desde la semana 13 el rol de laboratorio migra a apoyar el frontend. Revisar el reparto en la retrospectiva de cada sprint. | G8: Un integrante concentra más del 45% de los días estimados de un sprint. | H8: S7
A9: R-06 | B9: El escaneo genera tan pocos hallazgos que la priorización no se luce | C9: 2 | D9: 3 | E9: =C9*D9 -> 6 | F9: Usar ZAP en modo full scan sobre Juice Shop autenticado y verificar volumen en el S1. | G9: El escaneo baseline devuelve menos de 20 hallazgos distintos. | H9: S1
A10: R-07 | B10: La demo en vivo falla el día de la defensa | C10: 3 | D10: 4 | E10: =C10*D10 -> 12 | F10: Video de respaldo grabado en el S9 y ensayo en el equipo y la red reales de la sala. | G10: El ensayo en la sala no se alcanza a hacer antes de la última semana. | H10: S9
A11: R-08 | B11: Evidencias reunidas a última hora y quedan incompletas | C11: 3 | D11: 3 | E11: =C11*D11 -> 9 | F11: Cada evidencia tiene una tarea propia en el sprint donde nace, no en el S9. El S9 solo compila. | G11: Al cerrar el S6 falta alguna de las seis evidencias comprometidas. | H11: S9
A13: Exposición = probabilidad × impacto. Prob. e Impacto son estimaciones del equipo en escala 1 a 5 (celdas azules, editables).

Sheet Leyenda
A1: Cómo usar esta planilla
A3: Celdas que ustedes editan
A4: Sprints · D4 | B4: Fecha de inicio del sprint 1. Todas las demás fechas se calculan a partir de esta celda.
A5: Backlog · H (Responsable) | B5: Quién toma la tarea. Las celdas amarillas están sin asignar.
A6: Backlog · L (Estado) | B6: Pendiente / En curso / Bloqueado / Hecho. Al marcar Hecho, el % de avance del sprint se actualiza solo.
A7: Backlog · I (Días est.) | B7: Ajusten la estimación cuando la conozcan mejor. El total del sprint se recalcula.
A8: Riesgos · C y D | B8: Probabilidad e impacto de 1 a 5. La exposición se calcula sola.
A10: Convención de colores
A11: Texto azul | B11: Celda de entrada: dato que ustedes escriben o eligen.
A12: Relleno amarillo | B12: Pendiente de decidir. Hoy: los responsables aún no asignados.
A13: Texto negro | B13: Calculado por fórmula. No lo sobrescriban o rompen el avance.
A14: Tarea en cursiva gris | B14: Alcance opcional. Solo se aborda si el camino principal ya está cerrado.
A16: Ejemplo de fila ya completada
A17: Formato esperado | B17: T-005 | S1 | 1-2 | Laboratorio | Docker Compose con Juice Shop y PostgreSQL en red interna | Luciano Zambrano | 2 | Alta | Hecho
A19: Supuestos que usamos al armar esto
A20: Fecha de inicio | B20: 07-09-2026, fijada por nosotros. La presentación del anteproyecto está fechada 04-09-2026. Ajústenla al calendario real de Duoc.
A21: Responsables | B21: La propuesta solo nombra a Luciano Zambrano en Backend, Datos y Dashboard. Esas tareas quedaron pre-asignadas; el resto está en amarillo porque la propuesta no dice quién toma Arquitectura e IA ni Laboratorio y Validación.
A22: Días estimados | B22: Estimación nuestra en días-persona, sin base histórica del equipo. Revísenla en la primera planificación y corrijan la columna I.
A23: Nueve sprints de 2 semanas | B23: Derivado de los tres bloques de 6 semanas de la propuesta (semanas 1-6, 7-12 y 13-18).
A25: Dos cambios respecto de la propuesta original
A26: Ollama se prueba en la semana 1 | B26: La propuesta lo integra recién en las semanas 7 a 12. Si el hardware no da, enterarse en la semana 7 cuesta un tercio del proyecto.
A27: Se agrega un golden set en el S6 | B27: Sin medición contra anotación humana tienen una demo. Con ella tienen resultados: acierto OWASP, acierto de prioridad y tasa de alucinación.
